Workbook

Sheet Окно
A1: Перетаскивайте строки игроков между клубами. Зелёный = новый в клубе (IN). Счётчики IN/OUT — до 5.
A3: ="Цска "&MIN(5,SUMPRODUCT((LEN(A$5:A$33)>0)*(ISERROR(MATCH(A$5:A$33,_orig!$A$2:$A$27,0)))))&"/5 IN "&MIN(5,SUMPRODUCT((LEN(_orig!$A$2:$A$27)>0)*(ISERROR(MATCH(_orig!$A$2:$A$27,A$5:A$33,0)))))&"/5 OUT" | F3: ="Зенит "&MIN(5,SUMPRODUCT((LEN(F$5:F$33)>0)*(ISERROR(MATCH(F$5:F$33,_orig!$B$2:$B$25,0)))))&"/5 IN "&MIN(5,SUMPRODUCT((LEN(_orig!$B$2:$B$25)>0)*(ISERROR(MATCH(_orig!$B$2:$B$25,F$5:F$33,0)))))&"/5 OUT" | K3: ="Краснодар "&MIN(5,SUMPRODUCT((LEN(K$5:K$33)>0)*(ISERROR(MATCH(K$5:K$33,_orig!$C$2:$C$26,0)))))&"/5 IN "&MIN(5,SUMPRODUCT((LEN(_orig!$C$2:$C$26)>0)*(ISERROR(MATCH(_orig!$C$2:$C$26,K$5:K$33,0)))))&"/5 OUT" | P3: ="Локомотив "&MIN(5,SUMPRODUCT((LEN(P$5:P$33)>0)*(ISERROR(MATCH(P$5:P$33,_orig!$D$2:$D$26,0)))))&"/5 IN "&MIN(5,SUMPRODUCT((LEN(_orig!$D$2:$D$26)>0)*(ISERROR(MATCH(_orig!$D$2:$D$26,P$5:P$33,0)))))&"/5 OUT" | U3: ="Спартак "&MIN(5,SUMPRODUCT((LEN(U$5:U$33)>0)*(ISERROR(MATCH(U$5:U$33,_orig!$E$2:$E$25,0)))))&"/5 IN "&MIN(5,SUMPRODUCT((LEN(_orig!$E$2:$E$25)>0)*(ISERROR(MATCH(_orig!$E$2:$E$25,U$5:U$33,0)))))&"/5 OUT" | Z3: ="Динамо "&MIN(5,SUMPRODUCT((LEN(Z$5:Z$33)>0)*(ISERROR(MATCH(Z$5:Z$33,_orig!$F$2:$F$27,0)))))&"/5 IN "&MIN(5,SUMPRODUCT((LEN(_orig!$F$2:$F$27)>0)*(ISERROR(MATCH(_orig!$F$2:$F$27,Z$5:Z$33,0)))))&"/5 OUT" | AE3: ="Крылья Советов "&MIN(5,SUMPRODUCT((LEN(AE$5:AE$33)>0)*(ISERROR(MATCH(AE$5:AE$33,_orig!$G$2:$G$26,0)))))&"/5 IN "&MIN(5,SUMPRODUCT((LEN(_orig!$G$2:$G$26)>0)*(ISERROR(MATCH(_orig!$G$2:$G$26,AE$5:AE$33,0)))))&"/5 OUT" | AJ3: ="Урал "&MIN(5,SUMPRODUCT((LEN(AJ$5:AJ$33)>0)*(ISERROR(MATCH(AJ$5:AJ$33,_orig!$H$2:$H$26,0)))))&"/5 IN "&MIN(5,SUMPRODUCT((LEN(_orig!$H$2:$H$26)>0)*(ISERROR(MATCH(_orig!$H$2:$H$26,AJ$5:AJ$33,0)))))&"/5 OUT"
B4: старт | G4: старт | L4: старт | Q4: старт | V4: старт | AA4: старт | AF4: старт | AK4: старт
A5: Балогун | B5: ФРВ | C5: 79 | F5: Давид | G5: ФРВ | H5: 83 | K5: Буанга | L5: ЛФА | M5: 80 | P5: Бардакджы | Q5: ЦЗ | R5: 80 | U5: Орта | V5: ЦАП | W5: 82 | Z5: Альварез | AA5: ЦЗ | AB5: 83 | AE5: Бонджорно | AF5: ЦЗ | AG5: 78 | AJ5: Гудмундсон | AK5: ЦАП | AL5: 78
A6: Гроб | B6: ЦП | C6: 79 | F6: Кержаков | G6: ВРТ | H6: 82 | K6: Верету | L6: ЦП | M6: 80 | P6: Гедеш | Q6: ФРВ | R6: 79 | U6: Данк | V6: ЦЗ | W6: 81 | Z6: Карраскаль | AA6: ЦАП | AB6: 81 | AE6: Ито | AF6: ЛЗ | AG6: 78 | AJ6: Лафонт | AK6: ВРТ | AL6: 78
A7: Вебстер | B7: ЦЗ | C7: 78 | F7: Трехо | G7: ЦП | H7: 82 | K7: Лопез | L7: ВРТ | M7: 80 | P7: Муссо | Q7: ВРТ | R7: 79 | U7: Далот | V7: ЦП | W7: 80 | Z7: Хенри | AA7: ЛЗ | AB7: 80 | AE7: Фергюсон | AF7: ЦАП | AG7: 78 | AJ7: Ольсен | AK7: ЛФА | AL7: 78
A8: Симеоне | B8: ФРВ | C8: 78 | F8: Заха | G8: ЛФА | H8: 81 | K8: Клюверт | L8: ЦАП | M8: 79 | P8: Франковски | Q8: ПЗ | R8: 79 | U8: Мухтар | V8: ФРВ | W8: 80 | Z8: Шешко | AA8: ФРВ | AB8: 80 | AE8: Какерет | AF8: ЦП | AG8: 77 | AJ8: Каштанов | AK8: ФРВ | AL8: 77
A9: Спортиелло | B9: ВРТ | C9: 78 | F9: Фомин | G9: ЦАП | H9: 81 | K9: Умтити | L9: ЦЗ | M9: 79 | P9: Виффер | Q9: ЦП | R9: 78 | U9: Пепе | V9: ФРВ | W9: 80 | Z9: Альваро Гарсия | AA9: ЛФА | AB9: 79 | AE9: Ниакате | AF9: ЦЗ | AG9: 77 | AJ9: Егорычев | AK9: ЦП | AL9: 76
A10: Мойзес | B10: ЛЗ | C10: 77 | F10: Алип | G10: ЦЗ | H10: 80 | K10: Диоманде | L10: ЦЗ | M10: 78 | P10: Миранчук | Q10: ЦАП | R10: 78 | U10: Маркао | V10: ЦЗ | W10: 78 | Z10: Мауро | AA10: ПЗ | AB10: 79 | AE10: Рахманович | AF10: ЦП | AG10: 77 | AJ10: Бевеев | AK10: ПЗ | AL10: 75
A11: Тиллман | B11: ЦАП | C11: 77 | F11: Шутало | G11: ЦЗ | H11: 80 | K11: Жедсон | L11: ЦП | M11: 78 | P11: Кастильехо | Q11: ПФА | R11: 77 | U11: Маффео | V11: ПЗ | W11: 78 | Z11: Трубин | AA11: ВРТ | AB11: 79 | AE11: Гарре | AF11: ПФА | AG11: 76 | AJ11: Бегич | AK11: ЦЗ | AL11: 75
A12: Сако | B12: ПЗ | C12: 75 | F12: Абдулхамид | G12: ПЗ | H12: 78 | K12: Макс | L12: ЛЗ | M12: 78 | P12: Локо | Q12: ЛЗ | R12: 77 | U12: Зобнин | V12: ЦП | W12: 77 | Z12: Чавез | AA12: ЦП | AB12: 79 | AE12: Писарский | AF12: ФРВ | AG12: 76 | AJ12: Дмитриев | AK12: ПФА | AL12: 74
A13: Зджелар | B13: ЦЗ | C13: 73 | F13: Вильмар Барриос | G13: ЦП | H13: 78 | K13: Мата | L13: ПЗ | M13: 77 | P13: Теате | Q13: ЦЗ | R13: 77 | U13: Игнатов | V13: ЦП | W13: 75 | Z13: О'райли | AA13: ЦП | AB13: 78 | AE13: Ломаев | AF13: ВРТ | AG13: 74 | AJ13: Мишкич | AK13: ЦП | AL13: 72
A14: Мендес | B14: ЦП | C14: 73 | F14: Труфферт | G14: ЛЗ | H14: 77 | K14: Жуниор | L14: ПФА | M14: 76 | P14: Баринов | Q14: ЦП | R14: 75 | U14: Бабич | V14: ЛЗ | W14: 72 | Z14: Ругани | AA14: ЦЗ | AB14: 77 | AE14: Костанца | AF14: ПЗ | AG14: 73 | AJ14: Кики | AK14: ЛЗ | AL14: 71
A15: Дивеев | B15: ЦЗ | C15: 70 | F15: Нгамалу | G15: ПФА | H15: 76 | K15: Кокшаров | L15: ФРВ | M15: 75 | P15: Диатта | Q15: ЛФА | R15: 75 | U15: Селихов | V15: ВРТ | W15: 71 | Z15: Силас | AA15: ПФА | AB15: 76 | AE15: Салтыков | AF15: ЛФА | AG15: 73 | AJ15: Эмерсон | AK15: ЦЗ | AL15: 69
B16: запас | G16: запас | L16: запас | Q16: запас | V16: запас | AA16: запас | AF16: запас | AK16: запас
A17: Чилвелл | B17: ПЗ | C17: 80 | F17: Бовен | G17: ПФА | H17: 81 | K17: Ляказет | L17: ФРВ | M17: 83 | P17: Фабиански | Q17: ВРТ | R17: 79 | U17: Митома | V17: ЛФА | W17: 82 | Z17: Сангаре | AA17: ЦОП | AB17: 81 | AE17: Тарковски | AF17: ЦЗ | AG17: 79 | AJ17: Саванье | AK17: ЦАП | AL17: 80
A18: Манданда | B18: ВРТ | C18: 79 | F18: Сельс | G18: ВРТ | H18: 79 | K18: Теума | L18: ЦП | M18: 79 | P18: Чалов | Q18: ФРВ | R18: 78 | U18: Бето | V18: ФРВ | W18: 81 | Z18: Антонио | AA18: ФРВ | AB18: 78 | AE18: Гуаита | AF18: ВРТ | AG18: 78 | AJ18: Ареола | AK18: ВРТ | AL18: 78
A19: Заболотный | B19: ФРВ | C19: 76 | F19: Павар | G19: ЦЗ | H19: 78 | K19: Салах | L19: ПФА | M19: 78 | P19: Одриозола | Q19: ПЗ | R19: 76 | U19: Ми | V19: ЦЗ | W19: 79 | Z19: Ле Фе | AA19: ЦП | AB19: 77 | AE19: Дауд | AF19: ЦП | AG19: 78 | AJ19: Гиго | AK19: ЦЗ | AL19: 78
A20: Кучаев | B20: ЦАП | C20: 76 | F20: Эмболо | G20: ФРВ | H20: 78 | K20: Алонсо | L20: ЦЗ | M20: 77 | P20: Мартинш | Q20: ПП | R20: 75 | U20: Максименко | V20: ВРТ | W20: 77 | Z20: Тёрнер | AA20: ВРТ | AB20: 77 | AE20: Калимуендо | AF20: ФРВ | AG20: 76 | AJ20: Ранделович | AK20: ЛФА | AL20: 75
A21: Роша | B21: ЦЗ | C21: 76 | F21: Караваев | G21: ПЗ | H21: 74 | K21: Боржес | L21: ЦАП | M21: 73 | P21: Данило | Q21: ЦЗ | R21: 74 | U21: Мартинс | V21: ЦП | W21: 71 | Z21: Патрик | AA21: ЦЗ | AB21: 76 | AE21: Горшков | AF21: ЛЗ | AG21: 74 | AJ21: Биль | AK21: ПЗ | AL21: 72
A22: Адингра | B22: ЛФА | C22: 75 | F22: Ду Кейрош | G22: ЦП | H22: 73 | K22: Волков | L22: ПЗ | M22: 72 | P22: Пиняев | Q22: ЛФА | R22: 74 | U22: Пруцев | V22: ЦП | W22: 71 | Z22: Гиттенс | AA22: ЛФА | AB22: 75 | AE22: Бабкин | AF22: ЦАП | AG22: 73 | AJ22: Кокорин | AK22: ПФА | AL22: 72
A23: Мухин | B23: ЦП | C23: 71 | F23: Коваленко | G23: ЦАП | H23: 71 | K23: Агкацев | L23: ВРТ | M23: 71 | P23: Карпукас | Q23: ЦП | R23: 70 | U23: Рябчук | V23: ЛЗ | W23: 71 | Z23: Даса | AA23: ПЗ | AB23: 73 | AE23: Боргес | AF23: ЛП | AG23: 67 | AJ23: Палмер | AK23: ЦАП | AL23: 68
B24: резерв | G24: резерв | L24: резерв | Q24: резерв | V24: резерв | AA24: резерв | AF24: резерв | AK24: резерв
A25: Де Томас | B25: ФРВ | C25: 79 | F25: Градит | G25: ЦЗ | H25: 78 | K25: Милла | L25: ЦП | M25: 78 | P25: Капрари | Q25: ФРВ | R25: 77 | U25: Фуллкруг | V25: ФРВ | W25: 81 | Z25: Салемайкерс | AA25: ПФА | AB25: 78 | AE25: Риччи | AF25: ЦП | AG25: 75 | AJ25: Менди | AK25: ВРТ | AL25: 81
A26: Кайо Энрике | B26: ЛЗ | C26: 78 | F26: Паласиос | G26: ПФА | H26: 75 | K26: Тимбер | L26: ЦП | M26: 77 | P26: Минамино | Q26: ФРВ | R26: 76 | U26: Эдвардс | V26: ПФА | W26: 80 | Z26: Бальбуэна | AA26: ЦЗ | AB26: 76 | AE26: Эдуард | AF26: ФРВ | AG26: 75 | AJ26: Гуе | AK26: ЦП | AL26: 77
A27: Витинья | B27: ФРВ | C27: 76 | F27: Еракович | G27: ЦЗ | H27: 74 | K27: Черников | L27: ЦП | M27: 76 | P27: Глушенков | Q27: ПФА | R27: 75 | U27: Нандез | V27: ПФА | W27: 76 | Z27: Грулёв | AA27: ЛФА | AB27: 73 | AE27: Евгеньев | AF27: ЦЗ | AG27: 73 | AJ27: Мунетси | AK27: ЦП | AL27: 77
A28: Мудрык | B28: ФРВ | C28: 73 | F28: Ерохин | G28: ЦП | H28: 74 | K28: Барриос | L28: ЦОП | M28: 74 | P28: Сулейманов | Q28: ФРВ | R28: 73 | U28: Тезе | V28: ПЗ | W28: 76 | Z28: Маричаль | AA28: ЦЗ | AB28: 73 | AE28: Ежов | AF28: ПФА | AG28: 70 | AJ28: Лападула | AK28: ФРВ | AL28: 75
A29: Хелльвен | B29: ПЗ | C29: 73 | F29: Мантуан | G29: ЛФА | H29: 72 | K29: Кайо | L29: ЦЗ | M29: 74 | P29: Тикнизян | Q29: ПЗ | R29: 73 | U29: Зиньковский | V29: ЛФА | W29: 74 | Z29: Скопинцев | AA29: ЛЗ | AB29: 73 | AE29: Иванисеня | AF29: ЦП | AG29: 70 | AJ29: Мамин | AK29: ЦЗ | AL29: 72
A30: Файзуллаев | B30: ПФА | C30: 71 | F30: Чистяков | G30: ЦЗ | H30: 70 | K30: Олаза | L30: ЛЗ | M30: 74 | P30: Самошников | Q30: ЛЗ | R30: 71 | U30: Хлусевич | V30: ПЗ | W30: 71 | Z30: Фернандез | AA30: ЦЗ | AB30: 73 | AE30: Рассказов | AF30: ПЗ | AG30: 70 | AJ30: Газинский | AK30: ЦП | AL30: 71
A31: Агапов | B31: ЦЗ | C31: 68 | K31: Кривцов | L31: ЦАП | M31: 71 | P31: Сильянов | Q31: ПЗ | R31: 70 | Z31: Бителло | AA31: ЦАП | AB31: 71 | AE31: Йилдыз | AF31: ФРВ | AG31: 64 | AJ31: Юшин | AK31: ПФА | AL31: 71
A32: Ермаков | B32: ЦП | C32: 68 | Z32: Гагнидзе | AA32: ЦП | AB32: 68
A36: ="Сити "&MIN(5,SUMPRODUCT((LEN(A$38:A$66)>0)*(ISERROR(MATCH(A$38:A$66,_orig!$I$2:$I$26,0)))))&"/5 IN "&MIN(5,SUMPRODUCT((LEN(_orig!$I$2:$I$26)>0)*(ISERROR(MATCH(_orig!$I$2:$I$26,A$38:A$66,0)))))&"/5 OUT" | F36: ="Мю "&MIN(5,SUMPRODUCT((LEN(F$38:F$66)>0)*(ISERROR(MATCH(F$38:F$66,_orig!$J$2:$J$26,0)))))&"/5 IN "&MIN(5,SUMPRODUCT((LEN(_orig!$J$2:$J$26)>0)*(ISERROR(MATCH(_orig!$J$2:$J$26,F$38:F$66,0)))))&"/5 OUT" | K36: ="Ливерпуль "&MIN(5,SUMPRODUCT((LEN(K$38:K$66)>0)*(ISERROR(MATCH(K$38:K$66,_orig!$K$2:$K$26,0)))))&"/5 IN "&MIN(5,SUMPRODUCT((LEN(_orig!$K$2:$K$26)>0)*(ISERROR(MATCH(_orig!$K$2:$K$26,K$38:K$66,0)))))&"/5 OUT" | P36: ="Арсенал "&MIN(5,SUMPRODUCT((LEN(P$38:P$66)>0)*(ISERROR(MATCH(P$38:P$66,_orig!$L$2:$L$26,0)))))&"/5 IN "&MIN(5,SUMPRODUCT((LEN(_orig!$L$2:$L$26)>0)*(ISERROR(MATCH(_orig!$L$2:$L$26,P$38:P$66,0)))))&"/5 OUT" | U36: ="Астон Вилла "&MIN(5,SUMPRODUCT((LEN(U$38:U$66)>0)*(ISERROR(MATCH(U$38:U$66,_orig!$M$2:$M$28,0)))))&"/5 IN "&MIN(5,SUMPRODUCT((LEN(_orig!$M$2:$M$28)>0)*(ISERROR(MATCH(_orig!$M$2:$M$28,U$38:U$66,0)))))&"/5 OUT" | Z36: ="Челси "&MIN(5,SUMPRODUCT((LEN(Z$38:Z$66)>0)*(ISERROR(MATCH(Z$38:Z$66,_orig!$N$2:$N$26,0)))))&"/5 IN "&MIN(5,SUMPRODUCT((LEN(_orig!$N$2:$N$26)>0)*(ISERROR(MATCH(_orig!$N$2:$N$26,Z$38:Z$66,0)))))&"/5 OUT" | AE36: ="Тоттенхэм "&MIN(5,SUMPRODUCT((LEN(AE$38:AE$66)>0)*(ISERROR(MATCH(AE$38:AE$66,_orig!$O$2:$O$27,0)))))&"/5 IN "&MIN(5,SUMPRODUCT((LEN(_orig!$O$2:$O$27)>0)*(ISERROR(MATCH(_orig!$O$2:$O$27,AE$38:AE$66,0)))))&"/5 OUT" | AJ36: ="Ньюкасл "&MIN(5,SUMPRODUCT((LEN(AJ$38:AJ$66)>0)*(ISERROR(MATCH(AJ$38:AJ$66,_orig!$P$2:$P$26,0)))))&"/5 IN "&MIN(5,SUMPRODUCT((LEN(_orig!$P$2:$P$26)>0)*(ISERROR(MATCH(_orig!$P$2:$P$26,AJ$38:AJ$66,0)))))&"/5 OUT"
B37: старт | G37: старт | L37: старт | Q37: старт | V37: старт | AA37: старт | AF37: старт | AK37: старт
A38: Де Брюйне | B38: ЦАП | C38: 92 | F38: Фернандеш | G38: ЦАП | H38: 89 | K38: Алиссон | L38: ВРТ | M38: 90 | P38: Салиба | Q38: ЦЗ | R38: 89 | U38: Мартинез | V38: ВРТ | W38: 85 | Z38: Марез | AA38: ФРВ | AB38: 89 | AE38: Сон | AF38: ЛФА | AG38: 88 | AJ38: Буну | AK38: ВРТ | AL38: 85
A39: Месси | B39: ПФА | C39: 90 | F39: Каземиро | G39: ЦОП | H39: 87 | K39: Жота | L39: ФРВ | M39: 90 | P39: Одегаард | Q39: ЦАП | R39: 88 | U39: Джеймс | V39: ПЗ | W39: 84 | Z39: Сильва | AA39: ЦЗ | AB39: 86 | AE39: Мэддисон | AF39: ЦАП | AG39: 84 | AJ39: Трипье | AK39: ПЗ | AL39: 85
A40: Холанд | B40: ФРВ | C40: 90 | F40: Милинкович-Савич | G40: ЦП | H40: 87 | K40: Мбаппе | L40: ЛФА | M40: 90 | P40: Хаверц | Q40: ФРВ | R40: 88 | U40: Торрес | V40: ЦЗ | W40: 83 | Z40: Стерлинг | AA40: ЛФА | AB40: 86 | AE40: Хёйберг | AF40: ЦП | AG40: 84 | AJ40: Исак | AK40: ФРВ | AL40: 84
A41: Тонали | B41: ЦП | C41: 89 | F41: Де Лигт | G41: ЦЗ | H41: 86 | K41: Смоллинг | L41: ЦЗ | M41: 90 | P41: Мерино | Q41: ЦП | R41: 87 | U41: Гакпо | V41: ФРВ | W41: 82 | Z41: Фофана | AA41: ЦЗ | AB41: 85 | AE41: Бентанкур | AF41: ЦП | AG41: 82 | AJ41: Рафа | AK41: ЛФА | AL41: 84
A42: Габриэль | B42: ЦЗ | C42: 88 | F42: Онана | G42: ВРТ | H42: 86 | K42: Александер-Арнольд | L42: ПЗ | M42: 87 | P42: Коло Муани | Q42: ЛФА | R42: 86 | U42: Сперцян | V42: ФРВ | W42: 82 | Z42: Энцо | AA42: ЦП | AB42: 85 | AE42: Ван Де Вен | AF42: ЦЗ | AG42: 82 | AJ42: Ботман | AK42: ЦЗ | AL42: 83
A43: Рэшфорд | B43: ЛФА | C43: 86 | F43: Брозович | G43: ЦП | H43: 84 | K43: Робертсон | L43: ЛЗ | M43: 87 | P43: Райс | Q43: ЦП | R43: 86 | U43: Тилеманс | V43: ЦП | W43: 82 | Z43: Санчез | AA43: ВРТ | AB43: 84 | AE43: Ромеро | AF43: ЦЗ | AG43: 82 | AJ43: Шар | AK43: ЦЗ | AL43: 83
A44: Уокер | B44: ПЗ | C44: 86 | F44: Марсиаль | G44: ФРВ | H44: 84 | K44: Конате | L44: ЦЗ | M44: 86 | P44: Габриэль Жезус | Q44: ПФА | R44: 85 | U44: Конса | V44: ЛЗ | W44: 80 | Z44: Фекир | AA44: ЦАП | AB44: 84 | AE44: Викарио | AF44: ВРТ | AG44: 81 | AJ44: Уиллок | AK44: ЦП | AL44: 82
...

Sheet _orig
A1: Цска | B1: Зенит | C1: Краснодар | D1: Локомотив | E1: Спартак | F1: Динамо | G1: Крылья Советов | H1: Урал | I1: Сити | J1: Мю | K1: Ливерпуль | L1: Арсенал | M1: Астон Вилла | N1: Челси | O1: Тоттенхэм | P1: Ньюкасл | Q1: Реал | R1: Барселона | S1: Атлетико | T1: Атлетик | U1: Реал Сосьедад | V1: Севилья | W1: Жирона | X1: Бетис | Y1: Интер | Z1: Милан | AA1: Ювентус | AB1: Наполи | AC1: Аталанта | AD1: Фиорентина | AE1: Лацио | AF1: Рома | AG1: Бавария | AH1: Дортмунд | AI1: Байер | AJ1: Лейпциг | AK1: Франкфурт | AL1: Боруссия М | AM1: Вольфсбург | AN1: Хоффенхайм
A2: Балогун | B2: Давид | C2: Буанга | D2: Бардакджы | E2: Орта | F2: Альварез | G2: Бонджорно | H2: Гудмундсон | I2: Де Брюйне | J2: Фернандеш | K2: Алиссон | L2: Салиба | M2: Мартинез | N2: Марез | O2: Сон | P2: Буну | Q2: Кроос | R2: Лева | S2: Родри | T2: Леау | U2: Ремиро | V2: Гонсалвеш | W2: Газзанига | X2: Феликс | Y2: Берарди | Z2: Бензема | AA2: Влашич | AB2: Квара | AC2: Чесны | AD2: Гонзалез | AE2: Дардер | AF2: Гнабри | AG2: Кейн | AH2: Шлоттербек | AI2: Андрих | AJ2: Клаудиньо | AK2: Гётце | AL2: Кванкара | AM2: Кастилс | AN2: Аспас
A3: Гроб | B3: Кержаков | C3: Верету | D3: Гедеш | E3: Данк | F3: Карраскаль | G3: Ито | H3: Лафонт | I3: Месси | J3: Каземиро | K3: Жота | L3: Одегаард | M3: Джеймс | N3: Сильва | O3: Мэддисон | P3: Трипье | Q3: Нкунку | R3: Араухо | S3: Мората | T3: Сансет | U3: Вендел | V3: Рамос | W3: Жиру | X3: Шкриньяр | Y3: Зоммер | Z3: Вини | AA3: Проведель | AB3: Осимен | AC3: Миранчук | AD3: Секу Фофана | AE3: Торрес | AF3: Пеллегрини | AG3: Нойер | AH3: Кобель | AI3: Гримальдо | AJ3: Ольмо | AK3: Мусиаля | AL3: Кессие | AM3: Арнольд | AN3: Бауманн
A4: Вебстер | B4: Трехо | C4: Лопез | D4: Муссо | E4: Далот | F4: Хенри | G4: Фергюсон | H4: Ольсен | I4: Холанд | J4: Милинкович-Савич | K4: Мбаппе | L4: Хаверц | M4: Торрес | N4: Стерлинг | O4: Хёйберг | P4: Исак | Q4: Родриго | R4: Педри | S4: Облак | T4: Вивиан | U4: Ди Мария | V4: Лукебакио | W4: Эступинан | X4: Витинья | Y4: Мартинез | Z4: Терраччано | AA4: Костич | AB4: Мерет | AC4: Муриэль | AD4: Нзола | AE4: Камада | AF4: Патрисио | AG4: Дэвис | AH4: Дибала | AI4: Хофманн | AJ4: Вернер | AK4: Трапп | AL4: Ливакович | AM4: Майер | AN4: Диоп
A5: Симеоне | B5: Заха | C5: Клюверт | D5: Франковски | E5: Мухтар | F5: Шешко | G5: Какерет | H5: Каштанов | I5: Тонали | J5: Де Лигт | K5: Смоллинг | L5: Мерино | M5: Гакпо | N5: Фофана | O5: Бентанкур | P5: Рафа | Q5: Алаба | R5: Рафинья | S5: Рейнилдо | T5: Кулушевски | U5: Мендез | V5: Навас | W5: Алейш Гарсия | X5: Гидо Родригез | Y5: Барелла | Z5: Беннасер | AA5: Кьеза | AB5: Лоботка | AC5: Орбан | AD5: Мингз | AE5: Иммобиле | AF5: Азмун | AG5: Мин Дже | AH5: Мален | AI5: Градецки | AJ5: Доннарумма | AK5: Баку | AL5: Синистерра | AM5: Лакруа | AN5: Крамарич
A6: Спортиелло | B6: Фомин | C6: Умтити | D6: Виффер | E6: Пепе | F6: Альваро Гарсия | G6: Ниакате | H6: Егорычев | I6: Габриэль | J6: Онана | K6: Александер-Арнольд | L6: Коло Муани | M6: Сперцян | N6: Энцо | O6: Ван Де Вен | P6: Ботман | Q6: Браим | R6: Тер Штеген | S6: Лемар | T6: Муниаин | U6: Оярзабаль | V6: Итакура | W6: Перейра | X6: Иско | Y6: Арнаутович | Z6: Хакими | AA6: Альба | AB6: Рахмани | AC6: Пашалич | AD6: Садик | AE6: Лаззари | AF6: Кристанте | AG6: Упамекано | AH6: Фред | AI6: Иконе | AJ6: Опенда | AK6: Мармуш | AL6: Фелипе | AM6: Линдстром | AN6: Бакайоко
A7: Мойзес | B7: Алип | C7: Диоманде | D7: Миранчук | E7: Маркао | F7: Мауро | G7: Рахманович | H7: Бевеев | I7: Рэшфорд | J7: Брозович | K7: Робертсон | L7: Райс | M7: Тилеманс | N7: Санчез | O7: Ромеро | P7: Шар | Q7: Гарсия | R7: Бремер | S7: Молина | T7: Симон | U7: Кимпембе | V7: Карраско | W7: Мартинес | X7: Силва | Y7: Думфрис | Z7: Ангисса | AA7: Эн-Несри | AB7: Романьоли | AC7: Симонс | AD7: Бираги | AE7: Фраттези | AF7: Манчини | AG7: Горетцка | AH7: Джан | AI7: Лозано | AJ7: Иниго Мартинез | AK7: Кох | AL7: Хульманд | AM7: Нмеча | AN7: Гиббс-Уайт
A8: Тиллман | B8: Шутало | C8: Жедсон | D8: Кастильехо | E8: Маффео | F8: Трубин | G8: Гарре | H8: Бегич | I8: Уокер | J8: Марсиаль | K8: Конате | L8: Габриэль Жезус | M8: Конса | N8: Фекир | O8: Викарио | P8: Уиллок | Q8: Лукаку | R8: Канселу | S8: Льоренте | T8: Нико | U8: Фернандес | V8: Ундав | W8: Промес | X8: Галан | Y8: Чалханоглу | Z8: Рейндерс | AA8: Инасиу | AB8: Сака | AC8: Гайа | AD8: Ворд-Прауз | AE8: Бейси | AF8: Карсдорп | AG8: Киммих | AH8: Касьерра | AI8: Клаус | AJ8: Кокчу | AK8: Пачо | AL8: Гертруида | AM8: Виммер | AN8: Салай
A9: Сако | B9: Абдулхамид | C9: Макс | D9: Локо | E9: Зобнин | F9: Чавез | G9: Писарский | H9: Дмитриев | I9: Гвардиоль | J9: Ван-Биссака | K9: Коке | L9: Тимбер | M9: Морено | N9: Галлагер | O9: Порро | P9: Коне | Q9: Начо | R9: Неймар | S9: Савич | T9: Иньяки | U9: Тирни | V9: Льорис | W9: Пулишич | X9: Васкез | Y9: Бастони | Z9: Чуквуезе | AA9: Бах | AB9: Люка Эрнандез | AC9: Антониу Сильва | AD9: Сафонов | AE9: Касале | AF9: Пакета | AG9: Фримпонг | AH9: Адейеми | AI9: Руис | AJ9: Симакан | AK9: Тута | AL9: Вайгль | AM9: Маэле | AN9: Сугавару
A10: Зджелар | B10: Вильмар Барриос | C10: Мата | D10: Теате | E10: Игнатов | F10: О'райли | G10: Ломаев | H10: Мишкич | I10: Стоунз | J10: Хименес | K10: Собослай | L10: Рамсдейл | M10: Тодибо | N10: Маатсен | O10: Хулиан Альварез | P10: Перейра | Q10: Куртуа | R10: Де Йонг | S10: Обамеянг | T10: Траоре | U10: Элустондо | V10: Закария | W10: Эррера | X10: Ханко | Y10: Димарко | Z10: Эрнандез | AA10: Заир-Эмери | AB10: Ди Лоренцо | AC10: Илич | AD10: Нуньез | AE10: Машадо | AF10: Спиназолла | AG10: Коман | AH10: Мендеш | AI10: Синго | AJ10: Клостерманн | AK10: Дина Эбимбе | AL10: Коронадо | AM10: Сванберг | AN10: Доку
A11: Мендес | B11: Труфферт | C11: Жуниор | D11: Баринов | E11: Бабич | F11: Ругани | G11: Костанца | H11: Кики | I11: Палинья | J11: Маласия | K11: Гравенберх | L11: Акунья | M11: Ровелла | N11: Гюсто | O11: Куадрадо | P11: Эспино | Q11: Эриксен | R11: Бальде | S11: Джикия | T11: Йерай | U11: Лориент | V11: Каку | W11: Ангуло | X11: Эль Шарави | Y11: Мхитарян | Z11: Томори | AA11: Рейс | AB11: Невеш | AC11: Хатебур | AD11: Эллиотт | AE11: Шунин | AF11: Ндика | AG11: Рёль | AH11: Хуммельс | AI11: Гюлер | AJ11: Сейвальд | AK11: Корона | AL11: Нетц | AM11: Фишер | AN11: Керкес
A12: Дивеев | B12: Нгамалу | C12: Кокшаров | D12: Диатта | E12: Селихов | F12: Силас | G12: Салтыков | H12: Эмерсон | I12: Эдерсон | J12: Нуньес | K12: Олисе | L12: Диаш | M12: Рэмзи | N12: Мадуэке | O12: Сантос | P12: Хараслин | Q12: Лампти | R12: Гави | S12: Алмада | T12: Лоди | U12: Тюкавин | V12: Педроса | W12: Брабек | X12: Науфф | Y12: Кулибали | Z12: Тапсоба | AA12: Фаджиоли | AB12: Элмас | AC12: Торрес | AD12: Додо | AE12: Андерсон | AF12: Пайшао | AG12: Сане | AH12: Марушич | AI12: Хинкапи | AJ12: Раум | AK12: Нкунку | AL12: Телло | AM12: Борнау | AN12: Стах
... A24: Хелльвен | B24: Мантуан | C24: Кайо | D24: Тикнизян | E24: Зиньковский | F24: Скопинцев | G24: Иванисеня | H24: Мамин | I24: Вандерсон | J24: Пессина | K24: Гомес | L24: Дамсгаард | M24: Заниоло | N24: Морита | O24: Билинг | P24: Лонгстаф | Q24: Юсуф Фофана | R24: Дорли | S24: Сёюнджю | T24: Лерма | U24: Муньоз | V24: Сумаре | W24: Валери | X24: Нельсон | Y24: Миша | Z24: Пинеда | AA24: Коуто | AB24: Матеус Энрике | AC24: Баккер | AD24: Малком | AE24: Пеллегрини | AF24: Тейлор | AG24: Лаймер | AH24: Нмеча | AI24: Станишич | AJ24: Изуни | AK24: Ларссон | AL24: Фридрих | AM24: Буфаль | AN24: Кабак
A25: Файзуллаев | B25: Чистяков | C25: Олаза | D25: Самошников | E25: Хлусевич | F25: Фернандез | G25: Рассказов | H25: Газинский | I25: Брайда | J25: Диалло | K25: Браганса | L25: Кирех | M25: Ленглет | N25: Игорь | O25: Сессеньон | P25: Ливраменто | Q25: Калверт-Льюин | R25: Тавареш | S25: Альварез | T25: Шапаренко | U25: Чо | V25: Нианзу | W25: Торре | X25: Сабали | Y25: Уоткинс | Z25: Зубер | AA25: Камбиасо | AB25: Маммана | AC25: Холм | AD25: Соттил | AF25: Виктор | AG25: Мотинг | AH25: Галларно | AI25: Стиллер | AJ25: Хайдара | AL25: Себашё | AM25: Оздоев | AN25: Довбык
A26: Агапов | C26: Кривцов | D26: Сильянов | F26: Бителло | G26: Йилдыз | H26: Юшин | I26: Одои | J26: Эрик Санчес | K26: Микаутадзе | L26: Соланко | M26: Акпом | N26: Чалоба | O26: Диуф | P26: Колпани | Q26: Поттер | R26: Огбу | S26: Фернандо | T26: Иманол | Y26: Койта | Z26: Побега | AD26: Джене | AF26: Дилросун | AG26: Давсари | AH26: Мукоко | AJ26: Блашвич | AM26: Батши | AN26: Лекуе
A27: Ермаков | F27: Гагнидзе | M27: Траоре | O27: Семеньо | Z27: Тиау | AD27: Паризи | AH27: Шарахили | AJ27: Солет | AN27: Нсоки
M28: Хато | Z28: Эль Ямик | AJ28: Судаков | AN28: Джон
